<?xml version="1.0" ?>
<!-- =================================================================================== -->
<!-- |    This document was autogenerated by xacro from /home/gjohn/ros_ws/src/chargepal_description/urdf/bringups/primitive_chargepal_with_gripper.urdf.xacro | -->
<!-- |    EDITING THIS FILE BY HAND IS NOT RECOMMENDED                                 | -->
<!-- =================================================================================== -->
<robot name="primitive_chargepal_with_gripper">
  <!-- start kinematic chain -->
  <link name="world"/>
  <joint name="world_joint" type="fixed">
    <parent link="world"/>
    <child link="mobile_base_link"/>
    <origin rpy="0.0 0.0 0.0" xyz="-0.275 0.0 0.2"/>
  </joint>
  <link name="mobile_base_link">
    <inertial>
      <mass value="100.0"/>
      <origin rpy="0 0 0" xyz="0 0 0.4"/>
      <inertia ixx="4.136665012" ixy="0.0" ixz="0.0" iyy="6.666664000000002" iyz="0.0" izz="8.136663412"/>
    </inertial>
    <visual>
      <material name="grey">
        <color rgba="0.5 0.5 0.5 1"/>
      </material>
      <orign rpy="0.0 0.0 0.0" xyz="0.0 0.0 0.0"/>
      <geometry>
        <box size="0.8 0.58 0.4"/>
      </geometry>
    </visual>
    <collision>
      <orign rpy="0.0 0.0 0.0" xyz="0.0 0.0 0.0"/>
      <geometry>
        <box size="0.8 0.58 0.4"/>
      </geometry>
    </collision>
  </link>
  <joint name="tower_joint" type="fixed">
    <parent link="mobile_base_link"/>
    <child link="tower_link"/>
    <origin rpy="0.0 0.0 0.0" xyz="0.275 0.0 0.45"/>
  </joint>
  <link name="tower_link">
    <inertial>
      <mass value="50.0"/>
      <origin rpy="0 0 0" xyz="0 0 0.5"/>
      <inertia ixx="2.443332356" ixy="0.0" ixz="0.0" iyy="1.3020828125000001" iyz="0.0" izz="1.6620826684999999"/>
    </inertial>
    <visual>
      <material name="grey">
        <color rgba="0.5 0.5 0.5 1"/>
      </material>
      <orign rpy="0.0 0.0 0.0" xyz="0.0 0.0 0.0"/>
      <geometry>
        <box size="0.25 0.58 0.5"/>
      </geometry>
    </visual>
    <collision>
      <orign rpy="0.0 0.0 0.0" xyz="0.0 0.0 0.0"/>
      <geometry>
        <box size="0.25 0.58 0.5"/>
      </geometry>
    </collision>
  </link>
  <joint name="battery_joint" type="fixed">
    <parent link="mobile_base_link"/>
    <child link="battery_link"/>
    <origin rpy="0.0 0.0 0.0" xyz="-0.15 0.0 0.4"/>
  </joint>
  <link name="battery_link">
    <inertial>
      <mass value="300.0"/>
      <origin rpy="0 0 0" xyz="0 0 0.4"/>
      <inertia ixx="19.80061707975" ixy="0.0" ixz="0.0" iyy="11.562495375000003" iyz="0.0" izz="23.36311565475"/>
    </inertial>
    <visual>
      <material name="aluminium">
        <color rgba="0.8 0.8 0.8 1"/>
      </material>
      <orign rpy="0.0 0.0 0.0" xyz="0.0 0.0 0.0"/>
      <geometry>
        <box size="0.55 0.795 0.4"/>
      </geometry>
    </visual>
    <collision>
      <orign rpy="0.0 0.0 0.0" xyz="0.0 0.0 0.0"/>
      <geometry>
        <box size="0.55 0.795 0.4"/>
      </geometry>
    </collision>
  </link>
  <!-- colorize platform -->
  <gazebo reference="mobile_base_link">
    <material>Gazebo/DarkGrey</material>
  </gazebo>
  <gazebo reference="tower_link">
    <material>Gazebo/DarkGrey</material>
  </gazebo>
  <gazebo reference="battery_link">
    <material>Gazebo/Grey</material>
  </gazebo>
  <!-- platform arm joint -->
  <joint name="platform_ur10e_joint" type="fixed">
    <parent link="tower_link"/>
    <child link="base_link"/>
    <origin rpy="0.0 0.0 1.570795" xyz="0.0 0.0 0.25"/>
  </joint>
  <!--
    Base UR robot series xacro macro.

    NOTE: this is NOT a URDF. It cannot directly be loaded by consumers
    expecting a flattened '.urdf' file. See the top-level '.xacro' for that
    (but note: that .xacro must still be processed by the xacro command).

    For use in '.launch' files: use one of the 'load_urX.launch' convenience
    launch files.

    This file models the base kinematic chain of a UR robot, which then gets
    parameterised by various configuration files to convert it into a UR3(e),
    UR5(e), UR10(e) or UR16e.

    NOTE: the default kinematic parameters (ie: link lengths, frame locations,
    offets, etc) do not correspond to any particular robot. They are defaults
    only. There WILL be non-zero offsets between the Forward Kinematics results
    in TF (ie: robot_state_publisher) and the values reported by the Teach
    Pendant.

    For accurate (and robot-specific) transforms, the 'kinematics_parameters_file'
    parameter MUST point to a .yaml file containing the appropriate values for
    the targetted robot.

    If using the UniversalRobots/Universal_Robots_ROS_Driver, follow the steps
    described in the readme of that repository to extract the kinematic
    calibration from the controller and generate the required .yaml file.

    Main author of the migration to yaml configs: Ludovic Delval.

    Contributors to previous versions (in no particular order):

     - Felix Messmer
     - Kelsey Hawkins
     - Wim Meeussen
     - Shaun Edwards
     - Nadia Hammoudeh Garcia
     - Dave Hershberger
     - G. vd. Hoorn
     - Philip Long
     - Dave Coleman
     - Miguel Prada
     - Mathias Luedtke
     - Marcel Schnirring
     - Felix von Drigalski
     - Felix Exner
     - Jimmy Da Silva
     - Ajit Krisshna N L
     - Muhammad Asif Rana
  -->
  <!--
    NOTE: the macro defined in this file is NOT part of the public API of this
          package. Users CANNOT rely on this file being available, or stored in
          this location. Nor can they rely on the existence of the macro.
  -->
  <transmission name="shoulder_pan_trans">
    <type>transmission_interface/SimpleTransmission</type>
    <joint name="shoulder_pan_joint">
      <hardwareInterface>hardware_interface/VelocityJointInterface</hardwareInterface>
    </joint>
    <actuator name="shoulder_pan_motor">
      <mechanicalReduction>1</mechanicalReduction>
    </actuator>
  </transmission>
  <transmission name="shoulder_lift_trans">
    <type>transmission_interface/SimpleTransmission</type>
    <joint name="shoulder_lift_joint">
      <hardwareInterface>hardware_interface/VelocityJointInterface</hardwareInterface>
    </joint>
    <actuator name="shoulder_lift_motor">
      <mechanicalReduction>1</mechanicalReduction>
    </actuator>
  </transmission>
  <transmission name="elbow_trans">
    <type>transmission_interface/SimpleTransmission</type>
    <joint name="elbow_joint">
      <hardwareInterface>hardware_interface/VelocityJointInterface</hardwareInterface>
    </joint>
    <actuator name="elbow_motor">
      <mechanicalReduction>1</mechanicalReduction>
    </actuator>
  </transmission>
  <transmission name="wrist_1_trans">
    <type>transmission_interface/SimpleTransmission</type>
    <joint name="wrist_1_joint">
      <hardwareInterface>hardware_interface/VelocityJointInterface</hardwareInterface>
    </joint>
    <actuator name="wrist_1_motor">
      <mechanicalReduction>1</mechanicalReduction>
    </actuator>
  </transmission>
  <transmission name="wrist_2_trans">
    <type>transmission_interface/SimpleTransmission</type>
    <joint name="wrist_2_joint">
      <hardwareInterface>hardware_interface/VelocityJointInterface</hardwareInterface>
    </joint>
    <actuator name="wrist_2_motor">
      <mechanicalReduction>1</mechanicalReduction>
    </actuator>
  </transmission>
  <transmission name="wrist_3_trans">
    <type>transmission_interface/SimpleTransmission</type>
    <joint name="wrist_3_joint">
      <hardwareInterface>hardware_interface/VelocityJointInterface</hardwareInterface>
    </joint>
    <actuator name="wrist_3_motor">
      <mechanicalReduction>1</mechanicalReduction>
    </actuator>
  </transmission>
  <!-- links: main serial chain -->
  <link name="base_link"/>
  <link name="base_link_inertia">
    <visual>
      <origin rpy="0 0 3.141592653589793" xyz="0 0 0"/>
      <geometry>
        <mesh filename="package://ur_description/meshes/ur10e/visual/base.dae"/>
      </geometry>
      <material name="LightGrey">
        <color rgba="0.7 0.7 0.7 1.0"/>
      </material>
    </visual>
    <collision>
      <origin rpy="0 0 3.141592653589793" xyz="0 0 0"/>
      <geometry>
        <mesh filename="package://ur_description/meshes/ur10e/collision/base.stl"/>
      </geometry>
    </collision>
    <inertial>
      <mass value="4.0"/>
      <origin rpy="0 0 0" xyz="0 0 0"/>
      <inertia ixx="0.0061063308908" ixy="0.0" ixz="0.0" iyy="0.0061063308908" iyz="0.0" izz="0.01125"/>
    </inertial>
  </link>
  <link name="shoulder_link">
    <visual>
      <origin rpy="0 0 3.141592653589793" xyz="0 0 0"/>
      <geometry>
        <mesh filename="package://ur_description/meshes/ur10e/visual/shoulder.dae"/>
      </geometry>
      <material name="LightGrey">
        <color rgba="0.7 0.7 0.7 1.0"/>
      </material>
    </visual>
    <collision>
      <origin rpy="0 0 3.141592653589793" xyz="0 0 0"/>
      <geometry>
        <mesh filename="package://ur_description/meshes/ur10e/collision/shoulder.stl"/>
      </geometry>
    </collision>
    <inertial>
      <mass value="7.778"/>
      <origin rpy="0 0 0" xyz="0 0 0"/>
      <inertia ixx="0.03147431257693659" ixy="0.0" ixz="0.0" iyy="0.03147431257693659" iyz="0.0" izz="0.021875624999999996"/>
    </inertial>
  </link>
  <link name="upper_arm_link">
    <visual>
      <origin rpy="1.5707963267948966 0 -1.5707963267948966" xyz="0 0 0.1762"/>
      <geometry>
        <mesh filename="package://ur_description/meshes/ur10e/visual/upperarm.dae"/>
      </geometry>
      <material name="LightGrey">
        <color rgba="0.7 0.7 0.7 1.0"/>
      </material>
    </visual>
    <collision>
      <origin rpy="1.5707963267948966 0 -1.5707963267948966" xyz="0 0 0.1762"/>
      <geometry>
        <mesh filename="package://ur_description/meshes/ur10e/collision/upperarm.stl"/>
      </geometry>
    </collision>
    <inertial>
      <mass value="12.93"/>
      <origin rpy="0 1.5707963267948966 0" xyz="-0.306 0.0 0.175"/>
      <inertia ixx="0.42175380379841093" ixy="0.0" ixz="0.0" iyy="0.42175380379841093" iyz="0.0" izz="0.03636562499999999"/>
    </inertial>
  </link>
  <link name="forearm_link">
    <visual>
      <origin rpy="1.5707963267948966 0 -1.5707963267948966" xyz="0 0 0.0393"/>
      <geometry>
        <mesh filename="package://ur_description/meshes/ur10e/visual/forearm.dae"/>
      </geometry>
      <material name="LightGrey">
        <color rgba="0.7 0.7 0.7 1.0"/>
      </material>
    </visual>
    <collision>
      <origin rpy="1.5707963267948966 0 -1.5707963267948966" xyz="0 0 0.0393"/>
      <geometry>
        <mesh filename="package://ur_description/meshes/ur10e/collision/forearm.stl"/>
      </geometry>
    </collision>
    <inertial>
      <mass value="3.87"/>
      <origin rpy="0 1.5707963267948966 0" xyz="-0.285775 0.0 0.0393"/>
      <inertia ixx="0.11079302548902206" ixy="0.0" ixz="0.0" iyy="0.11079302548902206" iyz="0.0" izz="0.010884375"/>
    </inertial>
  </link>
  <link name="wrist_1_link">
    <visual>
      <!-- TODO: Move this to a parameter -->
      <origin rpy="1.5707963267948966 0 0" xyz="0 0 -0.135"/>
      <geometry>
        <mesh filename="package://ur_description/meshes/ur10e/visual/wrist1.dae"/>
      </geometry>
      <material name="LightGrey">
        <color rgba="0.7 0.7 0.7 1.0"/>
      </material>
    </visual>
    <collision>
      <origin rpy="1.5707963267948966 0 0" xyz="0 0 -0.135"/>
      <geometry>
        <mesh filename="package://ur_description/meshes/ur10e/collision/wrist1.stl"/>
      </geometry>
    </collision>
    <inertial>
      <mass value="1.96"/>
      <origin rpy="0 0 0" xyz="0 0 0"/>
      <inertia ixx="0.005108247956699999" ixy="0.0" ixz="0.0" iyy="0.005108247956699999" iyz="0.0" izz="0.005512499999999999"/>
    </inertial>
  </link>
  <link name="wrist_2_link">
    <visual>
      <origin rpy="0 0 0" xyz="0 0 -0.12"/>
      <geometry>
        <mesh filename="package://ur_description/meshes/ur10e/visual/wrist2.dae"/>
      </geometry>
      <material name="LightGrey">
        <color rgba="0.7 0.7 0.7 1.0"/>
      </material>
    </visual>
    <collision>
      <origin rpy="0 0 0" xyz="0 0 -0.12"/>
      <geometry>
        <mesh filename="package://ur_description/meshes/ur10e/collision/wrist2.stl"/>
      </geometry>
    </collision>
    <inertial>
      <mass value="1.96"/>
      <origin rpy="0 0 0" xyz="0 0 0"/>
      <inertia ixx="0.005108247956699999" ixy="0.0" ixz="0.0" iyy="0.005108247956699999" iyz="0.0" izz="0.005512499999999999"/>
    </inertial>
  </link>
  <link name="wrist_3_link">
    <visual>
      <origin rpy="1.5707963267948966 0 0" xyz="0 0 -0.1168"/>
      <geometry>
        <mesh filename="package://ur_description/meshes/ur10e/visual/wrist3.dae"/>
      </geometry>
      <material name="LightGrey">
        <color rgba="0.7 0.7 0.7 1.0"/>
      </material>
    </visual>
    <collision>
      <origin rpy="1.5707963267948966 0 0" xyz="0 0 -0.1168"/>
      <geometry>
        <mesh filename="package://ur_description/meshes/ur10e/collision/wrist3.stl"/>
      </geometry>
    </collision>
    <inertial>
      <mass value="0.202"/>
      <origin rpy="0 0 0" xyz="0.0 0.0 -0.025"/>
      <inertia ixx="0.00014434577559500002" ixy="0.0" ixz="0.0" iyy="0.00014434577559500002" iyz="0.0" izz="0.00020452500000000002"/>
    </inertial>
  </link>
  <!-- joints: main serial chain -->
  <joint name="base_link-base_link_inertia" type="fixed">
    <parent link="base_link"/>
    <child link="base_link_inertia"/>
    <!-- 'base_link' is REP-103 aligned (so X+ forward), while the internal
           frames of the robot/controller have X+ pointing backwards.
           Use the joint between 'base_link' and 'base_link_inertia' (a dummy
           link/frame) to introduce the necessary rotation over Z (of pi rad).
      -->
    <origin rpy="0 0 3.141592653589793" xyz="0 0 0"/>
  </joint>
  <joint name="shoulder_pan_joint" type="revolute">
    <parent link="base_link_inertia"/>
    <child link="shoulder_link"/>
    <origin rpy="0 0 0" xyz="0 0 0.1807"/>
    <axis xyz="0 0 1"/>
    <limit effort="330.0" lower="-3.141592653589793" upper="3.141592653589793" velocity="3.141592653589793"/>
    <dynamics damping="0" friction="0"/>
  </joint>
  <joint name="shoulder_lift_joint" type="revolute">
    <parent link="shoulder_link"/>
    <child link="upper_arm_link"/>
    <origin rpy="1.570796327 0 0" xyz="0 0 0"/>
    <axis xyz="0 0 1"/>
    <limit effort="330.0" lower="-3.141592653589793" upper="0.0" velocity="3.141592653589793"/>
    <dynamics damping="0" friction="0"/>
  </joint>
  <joint name="elbow_joint" type="revolute">
    <parent link="upper_arm_link"/>
    <child link="forearm_link"/>
    <origin rpy="0 0 0" xyz="-0.6127 0 0"/>
    <axis xyz="0 0 1"/>
    <limit effort="150.0" lower="-3.141592653589793" upper="0.0" velocity="3.141592653589793"/>
    <dynamics damping="0" friction="0"/>
  </joint>
  <joint name="wrist_1_joint" type="revolute">
    <parent link="forearm_link"/>
    <child link="wrist_1_link"/>
    <origin rpy="0 0 0" xyz="-0.57155 0 0.17415"/>
    <axis xyz="0 0 1"/>
    <limit effort="56.0" lower="-3.141592653589793" upper="3.141592653589793" velocity="3.141592653589793"/>
    <dynamics damping="0" friction="0"/>
  </joint>
  <joint name="wrist_2_joint" type="revolute">
    <parent link="wrist_1_link"/>
    <child link="wrist_2_link"/>
    <origin rpy="1.570796327 0 0" xyz="0 -0.11985 -2.458164590756244e-11"/>
    <axis xyz="0 0 1"/>
    <limit effort="56.0" lower="-3.141592653589793" upper="3.141592653589793" velocity="3.141592653589793"/>
    <dynamics damping="0" friction="0"/>
  </joint>
  <joint name="wrist_3_joint" type="revolute">
    <parent link="wrist_2_link"/>
    <child link="wrist_3_link"/>
    <origin rpy="1.570796326589793 3.141592653589793 3.141592653589793" xyz="0 0.11655 -2.390480459346185e-11"/>
    <axis xyz="0 0 1"/>
    <limit effort="56.0" lower="-0.7853981633974483" upper="5.497787143782138" velocity="3.141592653589793"/>
    <dynamics damping="0" friction="0"/>
  </joint>
  <!-- ROS-Industrial 'base' frame: base_link to UR 'Base' Coordinates transform -->
  <link name="base"/>
  <joint name="base_link-base_fixed_joint" type="fixed">
    <!-- Note the rotation over Z of pi radians: as base_link is REP-103
           aligned (ie: has X+ forward, Y+ left and Z+ up), this is needed
           to correctly align 'base' with the 'Base' coordinate system of
           the UR controller.
      -->
    <origin rpy="0 0 3.141592653589793" xyz="0 0 0"/>
    <parent link="base_link"/>
    <child link="base"/>
  </joint>
  <!-- ROS-Industrial 'flange' frame: attachment point for EEF models -->
  <link name="flange"/>
  <joint name="wrist_3-flange" type="fixed">
    <parent link="wrist_3_link"/>
    <child link="flange"/>
    <origin rpy="0 -1.5707963267948966 -1.5707963267948966" xyz="0 0 0"/>
  </joint>
  <!-- ROS-Industrial 'tool0' frame: all-zeros tool frame -->
  <link name="tool0"/>
  <joint name="flange-tool0" type="fixed">
    <!-- default toolframe: X+ left, Y+ up, Z+ front -->
    <origin rpy="1.5707963267948966 0 1.5707963267948966" xyz="0 0 0"/>
    <parent link="flange"/>
    <child link="tool0"/>
  </joint>
  <!-- Configure self collision properties per link -->
  <gazebo reference="shoulder_link">
    <selfCollide>true</selfCollide>
  </gazebo>
  <gazebo reference="upper_arm_link">
    <selfCollide>true</selfCollide>
  </gazebo>
  <gazebo reference="forearm_link">
    <selfCollide>true</selfCollide>
  </gazebo>
  <gazebo reference="wrist_1_link">
    <selfCollide>true</selfCollide>
  </gazebo>
  <gazebo reference="wrist_3_link">
    <selfCollide>true</selfCollide>
  </gazebo>
  <gazebo reference="wrist_2_link">
    <selfCollide>true</selfCollide>
  </gazebo>
  <gazebo reference="ee_link">
    <selfCollide>true</selfCollide>
  </gazebo>
  <!-- mount the fts to the robot -->
  <joint name="fts_fix" type="fixed">
    <!--In most cases origin would be flange adapter plate: <origin xyz="0 0 0.009" rpy="0 0 0"/> /-->
    <pose rpy="0 0 0" xyz="0 0 0"/>
    <parent link="tool0"/>
    <child link="fts_robotside"/>
  </joint>
  <link name="fts_robotside">
    <inertial>
      <origin rpy="0 0 0" xyz="0 0 0.01875"/>
      <mass value="0.3"/>
      <!-- <inertia ixx="0.000140625" ixy="0" ixz="0" iyy="0.000140625" iyz="0" izz="0.000246094" /> /-->
      <inertia ixx="0.000262" ixy="0" ixz="1" iyy="0.000265" iyz="1" izz="0.000219"/>
    </inertial>
    <visual>
      <origin rpy="0 0 1.5707963267948966" xyz="0 0 0"/>
      <geometry>
        <mesh filename="package://chargepal_description/meshes/robotiq_ft_300/visual/robotiq_ft_300.stl"/>
      </geometry>
      <material name="black">
        <color rgba="0.1 0.1 0.1 1"/>
      </material>
    </visual>
    <collision>
      <origin rpy="0 0 1.5707963267948966" xyz="0 0 0"/>
      <geometry>
        <mesh filename="package://chargepal_description/meshes/robotiq_ft_300/collision/robotiq_ft_300.stl"/>
      </geometry>
    </collision>
  </link>
  <gazebo reference="fts_robotside">
    <material>Gazebo/FlatBlack</material>
  </gazebo>
  <!-- virtual measurement frame -->
  <joint name="measurement_joint" type="fixed">
    <origin rpy="0 0 0" xyz="0 0 0.01625"/>
    <parent link="fts_robotside"/>
    <child link="robotiq_force_torque_frame_id"/>
  </joint>
  <link name="robotiq_force_torque_frame_id"/>
  <!-- toolside frame -->
  <joint name="toolside_joint" type="fixed">
    <origin rpy="0 0 0" xyz="0 0 0.0375"/>
    <parent link="fts_robotside"/>
    <child link="fts_toolside"/>
  </joint>
  <link name="fts_toolside"/>
  <!-- === 2x inner knuckle joint ================================================================================== -->
  <!-- === 2x finger tip joint (second movable joint in series) ===================================================== -->
  <!-- === 2x inner knuckle to inner finger joint ===================================================== -->
  <!-- === outer knuckle joint (first movable joint in series) ===================================================== -->
  <!-- =========================================================================================================== -->
  <gazebo>
    <plugin filename="libgazebo_grasp_fix.so" name="gazebo_grasp_fix">
      <arm>
        <arm_name>arm</arm_name>
        <palm_link>wrist_3_link</palm_link>
        <!-- NOTE: the commented-out links have fixed joints with other
               links, so they are not present in the SDF any more. -->
        <gripper_link>gripper_left_outer_knuckle          </gripper_link>
        <!-- <gripper_link>gripper_left_outer_finger           </gripper_link> -->
        <gripper_link>gripper_left_inner_finger           </gripper_link>
        <!-- <gripper_link>gripper_left_robotiq_fingertip_65mm </gripper_link> -->
        <gripper_link>gripper_left_inner_knuckle          </gripper_link>
        <gripper_link>gripper_right_inner_knuckle         </gripper_link>
        <gripper_link>gripper_right_outer_knuckle         </gripper_link>
        <!-- <gripper_link>gripper_right_outer_finger          </gripper_link> -->
        <gripper_link>gripper_right_inner_finger          </gripper_link>
        <!-- <gripper_link>gripper_right_robotiq_fingertip_65mm</gripper_link> -->
      </arm>
      <forces_angle_tolerance>120</forces_angle_tolerance>
      <update_rate>8</update_rate>
      <grip_count_threshold>4</grip_count_threshold>
      <max_grip_count>16</max_grip_count>
      <release_tolerance>0.01</release_tolerance>
      <disable_collisions_on_attach>false</disable_collisions_on_attach>
      <contact_topic>__default_topic__</contact_topic>
    </plugin>
  </gazebo>
  <joint name="ft300_coupling_joint" type="fixed">
    <origin rpy="0 0 -1.5707963267948966" xyz="0 0 0.004"/>
    <parent link="fts_toolside"/>
    <child link="gripper_coupling_link"/>
  </joint>
  <link name="gripper_coupling_link">
    <origin rpy="0 0 0" xyz="0 0 0"/>
    <visual>
      <origin rpy="0 0 0" xyz="0 0 0"/>
      <geometry>
        <cylinder length="0.014" radius="0.0375"/>
      </geometry>
      <material name="black">
        <color rgba="0.1 0.1 0.1 1"/>
      </material>
    </visual>
    <collision>
      <origin rpy="0 0 0" xyz="0 0 0"/>
      <geometry>
        <cylinder length="0.014" radius="0.0375"/>
      </geometry>
    </collision>
    <inertial>
      <mass value="0.1"/>
      <origin rpy="0 0 0" xyz="0.0 0.0 0.0"/>
      <inertia ixx="3.678956861749999e-05" ixy="0.0" ixz="0.0" iyy="3.678956861749999e-05" iyz="0.0" izz="7.03125e-05"/>
    </inertial>
  </link>
  <gazebo reference="gripper_coupling_link">
    <material>Gazebo/FlatBlack</material>
  </gazebo>
  <joint name="coupling_2f140_joint" type="fixed">
    <origin rpy="0 0 0" xyz="0 0 0.004"/>
    <parent link="gripper_coupling_link"/>
    <child link="gripper_robotiq_arg2f_base_link"/>
  </joint>
  <link name="gripper_robotiq_arg2f_base_link">
    <inertial>
      <origin rpy="0 0 0" xyz="8.625E-08 -4.6583E-06 0.03145"/>
      <mass value="0.22652"/>
      <inertia ixx="0.00020005" ixy="-4.2442E-10" ixz="-2.9069E-10" iyy="0.00017832" iyz="-3.4402E-08" izz="0.00013478"/>
    </inertial>
    <visual>
      <origin rpy="0 0 0" xyz="0 0 0"/>
      <geometry>
        <mesh filename="package://chargepal_description/meshes/robotiq_2f_140/robotiq_arg2f_base_link_fine.stl"/>
      </geometry>
      <material name="">
        <color rgba="0.1 0.1 0.1 1"/>
      </material>
    </visual>
    <collision>
      <origin rpy="0 0 0" xyz="0 0 0"/>
      <geometry>
        <mesh filename="package://chargepal_description/meshes/robotiq_2f_140/robotiq_arg2f_base_link_coarse.stl"/>
      </geometry>
    </collision>
  </link>
  <gazebo reference="gripper_robotiq_arg2f_base_link">
    <material>Gazebo/FlatBlack</material>
  </gazebo>
  <link name="gripper_left_outer_knuckle">
    <inertial>
      <origin rpy="0 0 0" xyz="-0.000200000000003065 0.0199435877845359 0.0292245259211331"/>
      <mass value="0.00853198276973456"/>
      <inertia ixx="2.89328108496468E-06" ixy="-1.57935047237397E-19" ixz="-1.93980378593255E-19" iyy="1.86719750325683E-06" iyz="-1.21858577871576E-06" izz="1.21905238907251E-06"/>
    </inertial>
    <visual>
      <origin rpy="0 0 0" xyz="0 0 0"/>
      <geometry>
        <mesh filename="package://chargepal_description/meshes/robotiq_2f_140/robotiq_arg2f_140_outer_knuckle.stl"/>
      </geometry>
      <material name="silver">
        <color rgba="0.79 0.82 0.93 1"/>
      </material>
    </visual>
    <collision>
      <origin rpy="0 0 0" xyz="0 0 0"/>
      <geometry>
        <mesh filename="package://chargepal_description/meshes/robotiq_2f_140/robotiq_arg2f_140_outer_knuckle.stl"/>
      </geometry>
    </collision>
  </link>
  <gazebo reference="gripper_left_outer_knuckle">
    <material>Gazebo/Grey</material>
  </gazebo>
  <link name="gripper_left_outer_finger">
    <inertial>
      <origin rpy="0 0 0" xyz="0.00030115855001899 0.0373907951953854 -0.0208027427000385"/>
      <mass value="0.022614240507152"/>
      <inertia ixx="1.52518312458174E-05" ixy="9.76583423954399E-10" ixz="-5.43838577022588E-10" iyy="6.17694243867776E-06" iyz="6.78636130740228E-06" izz="1.16494917907219E-05"/>
    </inertial>
    <visual>
      <origin rpy="0 0 0" xyz="0 0 0"/>
      <geometry>
        <mesh filename="package://chargepal_description/meshes/robotiq_2f_140/robotiq_arg2f_140_outer_finger.stl"/>
      </geometry>
      <material name="black">
        <color rgba="0.1 0.1 0.1 1"/>
      </material>
    </visual>
    <collision>
      <origin rpy="0 0 0" xyz="0 0 0"/>
      <geometry>
        <mesh filename="package://chargepal_description/meshes/robotiq_2f_140/robotiq_arg2f_140_outer_finger.stl"/>
      </geometry>
    </collision>
  </link>
  <gazebo reference="gripper_left_outer_finger">
    <material>Gazebo/FlatBlack</material>
  </gazebo>
  <link name="gripper_left_inner_finger">
    <inertial>
      <origin rpy="0 0 0" xyz="0.000299999999999317 0.0160078233491243 -0.0136945669206257"/>
      <mass value="0.0104003125914103"/>
      <inertia ixx="2.71909453810972E-06" ixy="1.35402465472579E-21" ixz="-7.1817349065269E-22" iyy="7.69100314106116E-07" iyz="6.74715432769696E-07" izz="2.30315190420171E-06"/>
    </inertial>
    <visual>
      <origin rpy="0 0 0" xyz="0 0 0"/>
      <geometry>
        <mesh filename="package://chargepal_description/meshes/robotiq_2f_140/robotiq_arg2f_140_inner_finger.stl"/>
      </geometry>
      <material name="black">
        <color rgba="0.1 0.1 0.1 1"/>
      </material>
    </visual>
    <collision>
      <origin rpy="0 0 0" xyz="0 0 0"/>
      <geometry>
        <mesh filename="package://chargepal_description/meshes/robotiq_2f_140/robotiq_arg2f_140_inner_finger.stl"/>
      </geometry>
    </collision>
  </link>
  <gazebo reference="gripper_left_inner_finger">
    <material>Gazebo/FlatBlack</material>
  </gazebo>
  <link name="gripper_left_inner_knuckle">
    <inertial>
      <origin rpy="0 0 0" xyz="0.000123011831763771 0.0507850843201817 0.00103968640075166"/>
      <mass value="0.0271177346495152"/>
      <inertia ixx="2.61910379223783E-05" ixy="-2.43616858946494E-07" ixz="-6.37789906117123E-09" iyy="2.8270243746167E-06" iyz="-5.37200748039765E-07" izz="2.83695868220296E-05"/>
    </inertial>
    <visual>
      <origin rpy="0 0 0" xyz="0 0 0"/>
      <geometry>
        <mesh filename="package://chargepal_description/meshes/robotiq_2f_140/robotiq_arg2f_140_inner_knuckle.stl"/>
      </geometry>
      <material name="black">
        <color rgba="0.1 0.1 0.1 1"/>
      </material>
    </visual>
    <collision>
      <origin rpy="0 0 0" xyz="0 0 0"/>
      <geometry>
        <mesh filename="package://chargepal_description/meshes/robotiq_2f_140/robotiq_arg2f_140_inner_knuckle.stl"/>
      </geometry>
    </collision>
  </link>
  <gazebo reference="gripper_left_inner_knuckle">
    <material>Gazebo/FlatBlack</material>
  </gazebo>
  <link name="gripper_right_outer_knuckle">
    <inertial>
      <origin rpy="0 0 0" xyz="-0.000200000000003065 0.0199435877845359 0.0292245259211331"/>
      <mass value="0.00853198276973456"/>
      <inertia ixx="2.89328108496468E-06" ixy="-1.57935047237397E-19" ixz="-1.93980378593255E-19" iyy="1.86719750325683E-06" iyz="-1.21858577871576E-06" izz="1.21905238907251E-06"/>
    </inertial>
    <visual>
      <origin rpy="0 0 0" xyz="0 0 0"/>
      <geometry>
        <mesh filename="package://chargepal_description/meshes/robotiq_2f_140/robotiq_arg2f_140_outer_knuckle.stl"/>
      </geometry>
      <material name="silver">
        <color rgba="0.79 0.82 0.93 1"/>
      </material>
    </visual>
    <collision>
      <origin rpy="0 0 0" xyz="0 0 0"/>
      <geometry>
        <mesh filename="package://chargepal_description/meshes/robotiq_2f_140/robotiq_arg2f_140_outer_knuckle.stl"/>
      </geometry>
    </collision>
  </link>
  <gazebo reference="gripper_right_outer_knuckle">
    <material>Gazebo/Grey</material>
  </gazebo>
  <link name="gripper_right_outer_finger">
    <inertial>
      <origin rpy="0 0 0" xyz="0.00030115855001899 0.0373907951953854 -0.0208027427000385"/>
      <mass value="0.022614240507152"/>
      <inertia ixx="1.52518312458174E-05" ixy="9.76583423954399E-10" ixz="-5.43838577022588E-10" iyy="6.17694243867776E-06" iyz="6.78636130740228E-06" izz="1.16494917907219E-05"/>
    </inertial>
    <visual>
      <origin rpy="0 0 0" xyz="0 0 0"/>
      <geometry>
        <mesh filename="package://chargepal_description/meshes/robotiq_2f_140/robotiq_arg2f_140_outer_finger.stl"/>
      </geometry>
      <material name="black">
        <color rgba="0.1 0.1 0.1 1"/>
      </material>
    </visual>
    <collision>
      <origin rpy="0 0 0" xyz="0 0 0"/>
      <geometry>
        <mesh filename="package://chargepal_description/meshes/robotiq_2f_140/robotiq_arg2f_140_outer_finger.stl"/>
      </geometry>
    </collision>
  </link>
  <gazebo reference="gripper_right_outer_finger">
    <material>Gazebo/FlatBlack</material>
  </gazebo>
  <link name="gripper_right_inner_finger">
    <inertial>
      <origin rpy="0 0 0" xyz="0.000299999999999317 0.0160078233491243 -0.0136945669206257"/>
      <mass value="0.0104003125914103"/>
      <inertia ixx="2.71909453810972E-06" ixy="1.35402465472579E-21" ixz="-7.1817349065269E-22" iyy="7.69100314106116E-07" iyz="6.74715432769696E-07" izz="2.30315190420171E-06"/>
    </inertial>
    <visual>
      <origin rpy="0 0 0" xyz="0 0 0"/>
      <geometry>
        <mesh filename="package://chargepal_description/meshes/robotiq_2f_140/robotiq_arg2f_140_inner_finger.stl"/>
      </geometry>
      <material name="black">
        <color rgba="0.1 0.1 0.1 1"/>
      </material>
    </visual>
    <collision>
      <origin rpy="0 0 0" xyz="0 0 0"/>
      <geometry>
        <mesh filename="package://chargepal_description/meshes/robotiq_2f_140/robotiq_arg2f_140_inner_finger.stl"/>
      </geometry>
    </collision>
  </link>
  <gazebo reference="gripper_right_inner_finger">
    <material>Gazebo/FlatBlack</material>
  </gazebo>
  <link name="gripper_right_inner_knuckle">
    <inertial>
      <origin rpy="0 0 0" xyz="0.000123011831763771 0.0507850843201817 0.00103968640075166"/>
      <mass value="0.0271177346495152"/>
      <inertia ixx="2.61910379223783E-05" ixy="-2.43616858946494E-07" ixz="-6.37789906117123E-09" iyy="2.8270243746167E-06" iyz="-5.37200748039765E-07" izz="2.83695868220296E-05"/>
    </inertial>
    <visual>
      <origin rpy="0 0 0" xyz="0 0 0"/>
      <geometry>
        <mesh filename="package://chargepal_description/meshes/robotiq_2f_140/robotiq_arg2f_140_inner_knuckle.stl"/>
      </geometry>
      <material name="black">
        <color rgba="0.1 0.1 0.1 1"/>
      </material>
    </visual>
    <collision>
      <origin rpy="0 0 0" xyz="0 0 0"/>
      <geometry>
        <mesh filename="package://chargepal_description/meshes/robotiq_2f_140/robotiq_arg2f_140_inner_knuckle.stl"/>
      </geometry>
    </collision>
  </link>
  <gazebo reference="gripper_right_inner_knuckle">
    <material>Gazebo/FlatBlack</material>
  </gazebo>
  <!-- = "left_outer_knuckle_joint" -->
  <joint name="gripper_finger_joint" type="revolute">
    <origin rpy="2.2957963267948966 0 0" xyz="0 -0.030601 0.054905"/>
    <parent link="gripper_robotiq_arg2f_base_link"/>
    <child link="gripper_left_outer_knuckle"/>
    <axis xyz="-1 0 0"/>
    <limit effort="1000" lower="0" upper="0.755" velocity="0.7"/>
    <dynamics damping="0.02" friction="0.0"/>
  </joint>
  <joint name="gripper_left_outer_finger_joint" type="fixed">
    <origin rpy="0 0 0" xyz="0 0.01821998610742 0.0260018192872234"/>
    <parent link="gripper_left_outer_knuckle"/>
    <child link="gripper_left_outer_finger"/>
    <axis xyz="1 0 0"/>
  </joint>
  <joint name="gripper_left_inner_knuckle_joint" type="revolute">
    <origin rpy="2.2957963267948966 0 0.0" xyz="0 -0.0127 0.06142"/>
    <parent link="gripper_robotiq_arg2f_base_link"/>
    <child link="gripper_left_inner_knuckle"/>
    <axis xyz="1 0 0"/>
    <limit effort="1000" lower="-0.8757" upper="0" velocity="0.7"/>
    <mimic joint="gripper_finger_joint" multiplier="-1" offset="0"/>
    <dynamics damping="0.02" friction="0.0"/>
  </joint>
  <joint name="gripper_left_inner_finger_joint" type="revolute">
    <origin rpy="-.725 0 0" xyz="0 0.0817554015893473 -0.0282203446692936"/>
    <parent link="gripper_left_outer_finger"/>
    <child link="gripper_left_inner_finger"/>
    <axis xyz="1 0 0"/>
    <limit effort="1000" lower="0" upper="0.8757" velocity="0.7"/>
    <mimic joint="gripper_finger_joint" multiplier="1" offset="0"/>
    <dynamics damping="0.001" friction="0.0"/>
  </joint>
  <!-- This joint closes the kinematic loop. Since loops are not allowed in URDF, but they are allowed in SDF, this is an SDF fragment. -->
  <gazebo>
    <joint name="gripper_left_inner_knuckle_to_finger_joint" type="revolute">
      <pose relative_to="gripper_left_inner_knuckle">0 0.1 -0.0022 0 0 0</pose>
      <axis>
        <xyz>1 0 0</xyz>
      </axis>
      <parent>gripper_left_inner_knuckle</parent>
      <child>gripper_left_inner_finger</child>
    </joint>
  </gazebo>
  <joint name="gripper_right_outer_knuckle_joint" type="revolute">
    <origin rpy="2.2957963267948966 0 3.141592653589793" xyz="0 0.030601 0.054905"/>
    <parent link="gripper_robotiq_arg2f_base_link"/>
    <child link="gripper_right_outer_knuckle"/>
    <axis xyz="1 0 0"/>
    <limit effort="1000" lower="-0.755" upper="0" velocity="0.7"/>
    <mimic joint="gripper_finger_joint" multiplier="-1" offset="0"/>
    <dynamics damping="0.02" friction="0.0"/>
  </joint>
  <joint name="gripper_right_outer_finger_joint" type="fixed">
    <origin rpy="0 0 0" xyz="0 0.01821998610742 0.0260018192872234"/>
    <parent link="gripper_right_outer_knuckle"/>
    <child link="gripper_right_outer_finger"/>
    <axis xyz="1 0 0"/>
  </joint>
  <joint name="gripper_right_inner_knuckle_joint" type="revolute">
    <origin rpy="2.2957963267948966 0 -3.141592653589793" xyz="0 0.0127 0.06142"/>
    <parent link="gripper_robotiq_arg2f_base_link"/>
    <child link="gripper_right_inner_knuckle"/>
    <axis xyz="1 0 0"/>
    <limit effort="1000" lower="-0.8757" upper="0" velocity="0.7"/>
    <mimic joint="gripper_finger_joint" multiplier="-1" offset="0"/>
    <dynamics damping="0.02" friction="0.0"/>
  </joint>
  <joint name="gripper_right_inner_finger_joint" type="revolute">
    <origin rpy="-.725 0 0" xyz="0 0.0817554015893473 -0.0282203446692936"/>
    <parent link="gripper_right_outer_finger"/>
    <child link="gripper_right_inner_finger"/>
    <axis xyz="1 0 0"/>
    <limit effort="1000" lower="0" upper="0.8757" velocity="0.7"/>
    <mimic joint="gripper_finger_joint" multiplier="1" offset="0"/>
    <dynamics damping="0.001" friction="0.0"/>
  </joint>
  <!-- This joint closes the kinematic loop. Since loops are not allowed in URDF, but they are allowed in SDF, this is an SDF fragment. -->
  <gazebo>
    <joint name="gripper_right_inner_knuckle_to_finger_joint" type="revolute">
      <pose relative_to="gripper_right_inner_knuckle">0 0.1 -0.0022 0 0 0</pose>
      <axis>
        <xyz>1 0 0</xyz>
      </axis>
      <parent>gripper_right_inner_knuckle</parent>
      <child>gripper_right_inner_finger</child>
    </joint>
  </gazebo>
  <transmission name="gripper_finger_joint_trans">
    <type>transmission_interface/SimpleTransmission</type>
    <joint name="gripper_finger_joint">
      <hardwareInterface>hardware_interface/PositionJointInterface</hardwareInterface>
    </joint>
    <actuator name="gripper_finger_joint_motor">
      <mechanicalReduction>1</mechanicalReduction>
    </actuator>
  </transmission>
  <link name="gripper_left_robotiq_fingertip_65mm">
    <inertial>
      <!-- <origin xyz="0 32.3E-03 -3.4587E-03" rpy="0 0 0" /> -->
      <origin rpy="3.141592653589793 1.5707963267948966 1.5707963267948966" xyz="0 0.0323 -0.003459"/>
      <mass value="3.3455E-2"/>
      <inertia ixx="13.66E-6" ixy="0" ixz="0" iyy="11.784E-6" iyz="0" izz="2.15E-6"/>
    </inertial>
    <visual>
      <origin rpy="0 0 0" xyz="0 0 0"/>
      <geometry>
        <mesh filename="package://chargepal_description/meshes/robotiq_2f_140/robotiq_arg2f_140_fingertip_65mm.stl"/>
      </geometry>
      <material name="robotiq_light_grey /">
        <color rgba="0.5 0.5 0.5 1"/>
      </material>
    </visual>
    <collision>
      <origin rpy="0 0 0" xyz="0 0 0"/>
      <geometry>
        <mesh filename="package://chargepal_description/meshes/robotiq_2f_140/robotiq_arg2f_140_fingertip_65mm.stl"/>
      </geometry>
    </collision>
  </link>
  <gazebo reference="gripper_left_robotiq_fingertip_65mm">
    <material>Gazebo/Grey</material>
  </gazebo>
  <link name="gripper_right_robotiq_fingertip_65mm">
    <inertial>
      <!-- <origin xyz="0 32.3E-03 -3.4587E-03" rpy="0 0 0" /> -->
      <origin rpy="3.141592653589793 1.5707963267948966 1.5707963267948966" xyz="0 0.0323 -0.003459"/>
      <mass value="3.3455E-2"/>
      <inertia ixx="13.66E-6" ixy="0" ixz="0" iyy="11.784E-6" iyz="0" izz="2.15E-6"/>
    </inertial>
    <visual>
      <origin rpy="0 0 0" xyz="0 0 0"/>
      <geometry>
        <mesh filename="package://chargepal_description/meshes/robotiq_2f_140/robotiq_arg2f_140_fingertip_65mm.stl"/>
      </geometry>
      <material name="robotiq_light_grey /">
        <color rgba="0.5 0.5 0.5 1"/>
      </material>
    </visual>
    <collision>
      <origin rpy="0 0 0" xyz="0 0 0"/>
      <geometry>
        <mesh filename="package://chargepal_description/meshes/robotiq_2f_140/robotiq_arg2f_140_fingertip_65mm.stl"/>
      </geometry>
    </collision>
  </link>
  <gazebo reference="gripper_right_robotiq_fingertip_65mm">
    <material>Gazebo/Grey</material>
  </gazebo>
  <joint name="gripper_left_fingertip_joint" type="fixed">
    <origin rpy="0 0 0" xyz="0 0.013513 -0.018469"/>
    <parent link="gripper_left_inner_finger"/>
    <child link="gripper_left_robotiq_fingertip_65mm"/>
    <axis xyz="0 0 1"/>
  </joint>
  <joint name="gripper_right_fingertip_joint" type="fixed">
    <origin rpy="0 0 0" xyz="0 0.013513 -0.018469"/>
    <parent link="gripper_right_inner_finger"/>
    <child link="gripper_right_robotiq_fingertip_65mm"/>
    <axis xyz="0 0 1"/>
  </joint>
  <!-- Tool Center Point: Center of the fingertips when gripper is closed -->
  <joint name="gripper_tcp_joint" type="fixed">
    <origin rpy="0 -1.5707963267948966 0" xyz="0 0 0.1975"/>
    <parent link="gripper_robotiq_arg2f_base_link"/>
    <child link="gripper_tcp"/>
  </joint>
  <link name="gripper_tcp"/>
  <gazebo>
    <plugin filename="libgazebo_ros_control.so" name="gazebo_ros_control">
      <controlPeriod>0.001</controlPeriod>
      <legacyModeNS>false</legacyModeNS>
    </plugin>
  </gazebo>
  <gazebo>
    <plugin filename="libroboticsgroup_gazebo_mimic_joint_plugin.so" name="gripper_right_outer_knucklemimic_joint_plugin">
      <joint>gripper_finger_joint</joint>
      <mimicJoint>gripper_right_outer_knuckle_joint</mimicJoint>
      <!-- if set to true, PID parameters from "/gazebo_ros_control/pid_gains/${mimic_joint}" are loaded -->
      <hasPID/>
      <multiplier>-1.0</multiplier>
      <offset>0</offset>
      <sensitiveness>0.0</sensitiveness>
      <!-- if absolute difference between setpoint and process value is below this threshold, do nothing; 0.0 = disable [rad] -->
      <maxEffort>10.0</maxEffort>
    </plugin>
  </gazebo>
</robot>

